#include<iostream>
#include<stdexcept>

void lanzaExcepcion() {
    throw std::runtime_error("Error en la funci贸n lanzaExcepcion");
}

int main() {
    try {
        try {
            lanzaExcepcion();
        }
        catch (const std::runtime_error& e) {
            std::cout << "Excepci贸n capturada y manejada. Reactivando..." << std::endl;
            throw; // Relanza la excepci贸n
        }
    }
    catch (const std::runtime_error& e) {
        std::cout << "Excepci贸n reactivada capturada: " << e.what() << std::endl;
    }

    return 0;
}